Errore durante il salvataggio dei dati Fitbit.
Errore database: (psycopg2.errors.InvalidTextRepresentation) invalid input value for enum vitalsigntype: "STEPS" [SQL: INSERT INTO vital_sign (patient_id, type, value, unit, recorded_at, origin, created_at) SELECT p0::INTEGER, p1::vitalsigntype, p2::FLOAT, p3::VARCHAR, p4::TIMESTAMP WITHOUT TIME ZONE, p5::dataorigin, p6::TIMESTAMP WITHOUT TIME ZONE FROM (VALUES (%(pa ... 8251 characters truncated ... 2, p3, p4, p5, p6, sen_counter) ORDER BY sen_counter RETURNING vital_sign.id, vital_sign.id AS id__1] [parameters: {'unit__0': 'bpm', 'recorded_at__0': datetime.datetime(2025, 4, 20, 19, 11, 42), 'origin__0': 'AUTOMATIC', 'type__0': 'HEART_RATE', 'created_at__0': datetime.datetime(2025, 4, 21, 19, 11, 44, 23661), 'patient_id__0': 1, 'value__0': 69, 'unit__1': 'bpm', 'recorded_at__1': datetime.datetime(2025, 4, 20, 20, 11, 42), 'origin__1': 'AUTOMATIC', 'type__1': 'HEART_RATE', 'created_at__1': datetime.datetime(2025, 4, 21, 19, 11, 44, 23664), 'patient_id__1': 1, 'value__1': 68, 'unit__2': 'bpm', 'recorded_at__2': datetime.datetime(2025, 4, 20, 21, 11, 42), 'origin__2': 'AUTOMATIC', 'type__2': 'HEART_RATE', 'created_at__2': datetime.datetime(2025, 4, 21, 19, 11, 44, 23666), 'patient_id__2': 1, 'value__2': 67, 'unit__3': 'bpm', 'recorded_at__3': datetime.datetime(2025, 4, 20, 22, 11, 42), 'origin__3': 'AUTOMATIC', 'type__3': 'HEART_RATE', 'created_at__3': datetime.datetime(2025, 4, 21, 19, 11, 44, 23667), 'patient_id__3': 1, 'value__3': 66, 'unit__4': 'bpm', 'recorded_at__4': datetime.datetime(2025, 4, 20, 23, 11, 42), 'origin__4': 'AUTOMATIC', 'type__4': 'HEART_RATE', 'created_at__4': datetime.datetime(2025, 4, 21, 19, 11, 44, 23674), 'patient_id__4': 1, 'value__4': 65, 'unit__5': 'bpm', 'recorded_at__5': datetime.datetime(2025, 4, 21, 0, 11, 42), 'origin__5': 'AUTOMATIC', 'type__5': 'HEART_RATE', 'created_at__5': datetime.datetime(2025, 4, 21, 19, 11, 44, 23674), 'patient_id__5': 1, 'value__5': 74, 'unit__6': 'bpm', 'recorded_at__6': datetime.datetime(2025, 4, 21, 1, 11, 42), 'origin__6': 'AUTOMATIC', 'type__6': 'HEART_RATE', 'created_at__6': datetime.datetime(2025, 4, 21, 19, 11, 44, 23675), 'patient_id__6': 1, 'value__6': 73, 'unit__7': 'bpm' ... 362 parameters truncated ... 'value__58': 8.3, 'unit__59': 'floors', 'recorded_at__59': datetime.datetime(2025, 4, 14, 0, 0), 'origin__59': 'AUTOMATIC', 'type__59': 'FLOORS_CLIMBED', 'created_at__59': datetime.datetime(2025, 4, 21, 19, 11, 44, 23699), 'patient_id__59': 1, 'value__59': 8, 'unit__60': 'floors', 'recorded_at__60': datetime.datetime(2025, 4, 15, 0, 0), 'origin__60': 'AUTOMATIC', 'type__60': 'FLOORS_CLIMBED', 'created_at__60': datetime.datetime(2025, 4, 21, 19, 11, 44, 23699), 'patient_id__60': 1, 'value__60': 9, 'unit__61': 'floors', 'recorded_at__61': datetime.datetime(2025, 4, 16, 0, 0), 'origin__61': 'AUTOMATIC', 'type__61': 'FLOORS_CLIMBED', 'created_at__61': datetime.datetime(2025, 4, 21, 19, 11, 44, 23699), 'patient_id__61': 1, 'value__61': 15, 'unit__62': 'floors', 'recorded_at__62': datetime.datetime(2025, 4, 17, 0, 0), 'origin__62': 'AUTOMATIC', 'type__62': 'FLOORS_CLIMBED', 'created_at__62': datetime.datetime(2025, 4, 21, 19, 11, 44, 23699), 'patient_id__62': 1, 'value__62': 14, 'unit__63': 'floors', 'recorded_at__63': datetime.datetime(2025, 4, 18, 0, 0), 'origin__63': 'AUTOMATIC', 'type__63': 'FLOORS_CLIMBED', 'created_at__63': datetime.datetime(2025, 4, 21, 19, 11, 44, 23700), 'patient_id__63': 1, 'value__63': 16, 'unit__64': 'floors', 'recorded_at__64': datetime.datetime(2025, 4, 19, 0, 0), 'origin__64': 'AUTOMATIC', 'type__64': 'FLOORS_CLIMBED', 'created_at__64': datetime.datetime(2025, 4, 21, 19, 11, 44, 23700), 'patient_id__64': 1, 'value__64': 9, 'unit__65': 'floors', 'recorded_at__65': datetime.datetime(2025, 4, 20, 0, 0), 'origin__65': 'AUTOMATIC', 'type__65': 'FLOORS_CLIMBED', 'created_at__65': datetime.datetime(2025, 4, 21, 19, 11, 44, 23700), 'patient_id__65': 1, 'value__65': 13}] (Background on this error at: https://sqlalche.me/e/20/9h9h)